Workbook

Sheet Sheet1
A1: Class | B1: Geology | C1: ROCKTYPE | D1: MIN_AGE | E1: MAX_AGE | F1: Hydrolithology | G1: Assignment note | H1: log10 k (m2) | I1: Ksat (m/s) | J1: Ksat (m/day) | K1: Alt hydrolithology | L1: Alt Ksat (m/day)
A2: 1 | B2: Qvm | C2: Volcanic | D2: Quaternary | E2: Quaternary | F2: Volcanic rocks | G2: Volcanic rocks | H2: =IFERROR(INDEX(Ksat_Lookup!$B$9:$B$18,MATCH(F2,Ksat_Lookup!$A$9:$A$18,0)),"") -> -12.5 | I2: =IF(H2="","",10^H2*Ksat_Lookup!$B$5) -> 3.1021944e-06 | J2: =IF(I2="","",I2*Ksat_Lookup!$B$6) -> 0.26802959
A3: 2 | B3: TQvm | C3: Volcanic | D3: Quaternary | E3: Tertiary | F3: Volcanic rocks | G3: Volcanic rocks | H3: =IFERROR(INDEX(Ksat_Lookup!$B$9:$B$18,MATCH(F3,Ksat_Lookup!$A$9:$A$18,0)),"") -> -12.5 | I3: =IF(H3="","",10^H3*Ksat_Lookup!$B$5) -> 3.1021944e-06 | J3: =IF(I3="","",I3*Ksat_Lookup!$B$6) -> 0.26802959
A4: 3 | B4: PTR | C4: Sedimentary | D4: Triassic | E4: Permian | F4: Siliciclastic sedimentary rocks | G4: Pre-Quaternary sedimentary rock (lithology not given) -> siliciclastic, undifferentiated | H4: =IFERROR(INDEX(Ksat_Lookup!$B$9:$B$18,MATCH(F4,Ksat_Lookup!$A$9:$A$18,0)),"") -> -15.2 | I4: =IF(H4="","",10^H4*Ksat_Lookup!$B$5) -> 6.1896915e-09 | J4: =IF(I4="","",I4*Ksat_Lookup!$B$6) -> 0.00053478935
A5: 4 | B5: Q | C5: Sedimentary | D5: Quaternary | E5: Quaternary | F5: Unconsolidated sediments | G5: Quaternary sediments -> unconsolidated | H5: =IFERROR(INDEX(Ksat_Lookup!$B$9:$B$18,MATCH(F5,Ksat_Lookup!$A$9:$A$18,0)),"") -> -13 | I5: =IF(H5="","",10^H5*Ksat_Lookup!$B$5) -> 9.81e-07 | J5: =IF(I5="","",I5*Ksat_Lookup!$B$6) -> 0.0847584
A6: 5 | B6: ZD | C6: Sedimentary | D6: Devonian | E6: Late Proterozoic | F6: Siliciclastic sedimentary rocks | G6: Pre-Quaternary sedimentary rock (lithology not given) -> siliciclastic, undifferentiated | H6: =IFERROR(INDEX(Ksat_Lookup!$B$9:$B$18,MATCH(F6,Ksat_Lookup!$A$9:$A$18,0)),"") -> -15.2 | I6: =IF(H6="","",10^H6*Ksat_Lookup!$B$5) -> 6.1896915e-09 | J6: =IF(I6="","",I6*Ksat_Lookup!$B$6) -> 0.00053478935
A7: 6 | B7: uK | C7: Sedimentary | D7: Upper Cretaceous | E7: Upper Cretaceous | F7: Siliciclastic sedimentary rocks | G7: Pre-Quaternary sedimentary rock (lithology not given) -> siliciclastic, undifferentiated | H7: =IFERROR(INDEX(Ksat_Lookup!$B$9:$B$18,MATCH(F7,Ksat_Lookup!$A$9:$A$18,0)),"") -> -15.2 | I7: =IF(H7="","",10^H7*Ksat_Lookup!$B$5) -> 6.1896915e-09 | J7: =IF(I7="","",I7*Ksat_Lookup!$B$6) -> 0.00053478935
A8: 7 | B8: MZsv | C8: Volcanic | D8: Mesozoic | E8: Mesozoic | F8: Mixed sedimentary-volcanic | G8: 'sv' = sedimentary and volcanic rocks -> log-average of the two | H8: =IFERROR(INDEX(Ksat_Lookup!$B$9:$B$18,MATCH(F8,Ksat_Lookup!$A$9:$A$18,0)),"") -> -13.85 | I8: =IF(H8="","",10^H8*Ksat_Lookup!$B$5) -> 1.3856993e-07 | J8: =IF(I8="","",I8*Ksat_Lookup!$B$6) -> 0.011972442
A9: 8 | B9: eTvm* | C9: Volcanic | D9: Eocene | E9: Eocene | F9: Volcanic rocks | G9: Volcanic rocks | H9: =IFERROR(INDEX(Ksat_Lookup!$B$9:$B$18,MATCH(F9,Ksat_Lookup!$A$9:$A$18,0)),"") -> -12.5 | I9: =IF(H9="","",10^H9*Ksat_Lookup!$B$5) -> 3.1021944e-06 | J9: =IF(I9="","",I9*Ksat_Lookup!$B$6) -> 0.26802959
A10: 9 | B10: K | C10: Sedimentary | D10: Cretaceous | E10: Cretaceous | F10: Siliciclastic sedimentary rocks | G10: Pre-Quaternary sedimentary rock (lithology not given) -> siliciclastic, undifferentiated | H10: =IFERROR(INDEX(Ksat_Lookup!$B$9:$B$18,MATCH(F10,Ksat_Lookup!$A$9:$A$18,0)),"") -> -15.2 | I10: =IF(H10="","",10^H10*Ksat_Lookup!$B$5) -> 6.1896915e-09 | J10: =IF(I10="","",I10*Ksat_Lookup!$B$6) -> 0.00053478935
A11: 10 | B11: JKsv | C11: Volcanic | D11: Cretaceous | E11: Jurassic | F11: Mixed sedimentary-volcanic | G11: 'sv' = sedimentary and volcanic rocks -> log-average of the two | H11: =IFERROR(INDEX(Ksat_Lookup!$B$9:$B$18,MATCH(F11,Ksat_Lookup!$A$9:$A$18,0)),"") -> -13.85 | I11: =IF(H11="","",10^H11*Ksat_Lookup!$B$5) -> 1.3856993e-07 | J11: =IF(I11="","",I11*Ksat_Lookup!$B$6) -> 0.011972442
A12: 11 | B12: nT | C12: Sedimentary | D12: Neogene | E12: Neogene | F12: Siliciclastic sedimentary rocks | G12: Pre-Quaternary sedimentary rock (lithology not given) -> siliciclastic, undifferentiated | H12: =IFERROR(INDEX(Ksat_Lookup!$B$9:$B$18,MATCH(F12,Ksat_Lookup!$A$9:$A$18,0)),"") -> -15.2 | I12: =IF(H12="","",10^H12*Ksat_Lookup!$B$5) -> 6.1896915e-09 | J12: =IF(I12="","",I12*Ksat_Lookup!$B$6) -> 0.00053478935
A13: 12 | B13: Ice | C13: Ice | D13: Holocene | E13: Holocene | F13: No data | G13: Not a geologic unit (water/ice/other/unknown) - no Ksat | H13: =IFERROR(INDEX(Ksat_Lookup!$B$9:$B$18,MATCH(F13,Ksat_Lookup!$A$9:$A$18,0)),"") | I13: =IF(H13="","",10^H13*Ksat_Lookup!$B$5) | J13: =IF(I13="","",I13*Ksat_Lookup!$B$6)
... A34: 33 | B34: eTsv | C34: Volcanic | D34: Eocene | E34: Eocene | F34: Mixed sedimentary-volcanic | G34: 'sv' = sedimentary and volcanic rocks -> log-average of the two | H34: =IFERROR(INDEX(Ksat_Lookup!$B$9:$B$18,MATCH(F34,Ksat_Lookup!$A$9:$A$18,0)),"") -> -13.85 | I34: =IF(H34="","",10^H34*Ksat_Lookup!$B$5) -> 1.3856993e-07 | J34: =IF(I34="","",I34*Ksat_Lookup!$B$6) -> 0.011972442
A35: 34 | B35: TQ | C35: Sedimentary | D35: Quaternary | E35: Tertiary | F35: Unconsolidated sediments | G35: Quaternary-Tertiary/Neogene sediments; may be partly consolidated | H35: =IFERROR(INDEX(Ksat_Lookup!$B$9:$B$18,MATCH(F35,Ksat_Lookup!$A$9:$A$18,0)),"") -> -13 | I35: =IF(H35="","",10^H35*Ksat_Lookup!$B$5) -> 9.81e-07 | J35: =IF(I35="","",I35*Ksat_Lookup!$B$6) -> 0.0847584 | K35: Siliciclastic sedimentary rocks | L35: =10^INDEX(Ksat_Lookup!$B$9:$B$18,MATCH(K35,Ksat_Lookup!$A$9:$A$18,0))*Ksat_Lookup!$B$5*Ksat_Lookup!$B$6 -> 0.00053478935
A36: 35 | B36: eT | C36: Sedimentary | D36: Eocene | E36: Eocene | F36: Siliciclastic sedimentary rocks | G36: Pre-Quaternary sedimentary rock (lithology not given) -> siliciclastic, undifferentiated | H36: =IFERROR(INDEX(Ksat_Lookup!$B$9:$B$18,MATCH(F36,Ksat_Lookup!$A$9:$A$18,0)),"") -> -15.2 | I36: =IF(H36="","",10^H36*Ksat_Lookup!$B$5) -> 6.1896915e-09 | J36: =IF(I36="","",I36*Ksat_Lookup!$B$6) -> 0.00053478935
A37: 36 | B37: KT | C37: Sedimentary | D37: Tertiary | E37: Cretaceous | F37: Siliciclastic sedimentary rocks | G37: Pre-Quaternary sedimentary rock (lithology not given) -> siliciclastic, undifferentiated | H37: =IFERROR(INDEX(Ksat_Lookup!$B$9:$B$18,MATCH(F37,Ksat_Lookup!$A$9:$A$18,0)),"") -> -15.2 | I37: =IF(H37="","",10^H37*Ksat_Lookup!$B$5) -> 6.1896915e-09 | J37: =IF(I37="","",I37*Ksat_Lookup!$B$6) -> 0.00053478935
A38: 37 | B38: plT | C38: Sedimentary | D38: Pliocene | E38: Pliocene | F38: Siliciclastic sedimentary rocks | G38: Pre-Quaternary sedimentary rock (lithology not given) -> siliciclastic, undifferentiated | H38: =IFERROR(INDEX(Ksat_Lookup!$B$9:$B$18,MATCH(F38,Ksat_Lookup!$A$9:$A$18,0)),"") -> -15.2 | I38: =IF(H38="","",10^H38*Ksat_Lookup!$B$5) -> 6.1896915e-09 | J38: =IF(I38="","",I38*Ksat_Lookup!$B$6) -> 0.00053478935
A39: 38 | B39: Jvm | C39: Volcanic | D39: Jurassic | E39: Jurassic | F39: Volcanic rocks | G39: Volcanic rocks | H39: =IFERROR(INDEX(Ksat_Lookup!$B$9:$B$18,MATCH(F39,Ksat_Lookup!$A$9:$A$18,0)),"") -> -12.5 | I39: =IF(H39="","",10^H39*Ksat_Lookup!$B$5) -> 3.1021944e-06 | J39: =IF(I39="","",I39*Ksat_Lookup!$B$6) -> 0.26802959
A40: 39 | B40: eTvm | C40: Volcanic | D40: Eocene | E40: Eocene | F40: Volcanic rocks | G40: Volcanic rocks | H40: =IFERROR(INDEX(Ksat_Lookup!$B$9:$B$18,MATCH(F40,Ksat_Lookup!$A$9:$A$18,0)),"") -> -12.5 | I40: =IF(H40="","",10^H40*Ksat_Lookup!$B$5) -> 3.1021944e-06 | J40: =IF(I40="","",I40*Ksat_Lookup!$B$6) -> 0.26802959
A41: 40 | B41: pgTvm | C41: Volcanic | D41: Paleogene | E41: Paleogene | F41: Volcanic rocks | G41: Volcanic rocks | H41: =IFERROR(INDEX(Ksat_Lookup!$B$9:$B$18,MATCH(F41,Ksat_Lookup!$A$9:$A$18,0)),"") -> -12.5 | I41: =IF(H41="","",10^H41*Ksat_Lookup!$B$5) -> 3.1021944e-06 | J41: =IF(I41="","",I41*Ksat_Lookup!$B$6) -> 0.26802959
A42: 41 | B42: Jvi | C42: Volcanic | D42: Jurassic | E42: Jurassic | F42: Volcanic rocks | G42: Volcanic rocks | H42: =IFERROR(INDEX(Ksat_Lookup!$B$9:$B$18,MATCH(F42,Ksat_Lookup!$A$9:$A$18,0)),"") -> -12.5 | I42: =IF(H42="","",10^H42*Ksat_Lookup!$B$5) -> 3.1021944e-06 | J42: =IF(I42="","",I42*Ksat_Lookup!$B$6) -> 0.26802959
A43: 42 | B43: J | C43: Sedimentary | D43: Jurassic | E43: Jurassic | F43: Siliciclastic sedimentary rocks | G43: Pre-Quaternary sedimentary rock (lithology not given) -> siliciclastic, undifferentiated | H43: =IFERROR(INDEX(Ksat_Lookup!$B$9:$B$18,MATCH(F43,Ksat_Lookup!$A$9:$A$18,0)),"") -> -15.2 | I43: =IF(H43="","",10^H43*Ksat_Lookup!$B$5) -> 6.1896915e-09 | J43: =IF(I43="","",I43*Ksat_Lookup!$B$6) -> 0.00053478935
A44: 43 | B44: DPv | C44: Volcanic | D44: Permian | E44: Devonian | F44: Volcanic rocks | G44: Volcanic rocks | H44: =IFERROR(INDEX(Ksat_Lookup!$B$9:$B$18,MATCH(F44,Ksat_Lookup!$A$9:$A$18,0)),"") -> -12.5 | I44: =IF(H44="","",10^H44*Ksat_Lookup!$B$5) -> 3.1021944e-06 | J44: =IF(I44="","",I44*Ksat_Lookup!$B$6) -> 0.26802959
A45: 44 | B45: lmJvi | C45: Volcanic | D45: Middle Jurassic | E45: Lower Jurassic | F45: Volcanic rocks | G45: Volcanic rocks | H45: =IFERROR(INDEX(Ksat_Lookup!$B$9:$B$18,MATCH(F45,Ksat_Lookup!$A$9:$A$18,0)),"") -> -12.5 | I45: =IF(H45="","",10^H45*Ksat_Lookup!$B$5) -> 3.1021944e-06 | J45: =IF(I45="","",I45*Ksat_Lookup!$B$6) -> 0.26802959
A46: 45 | B46: lmJv | C46: Volcanic | D46: Middle Jurassic | E46: Lower Jurassic | F46: Volcanic rocks | G46: Volcanic rocks | H46: =IFERROR(INDEX(Ksat_Lookup!$B$9:$B$18,MATCH(F46,Ksat_Lookup!$A$9:$A$18,0)),"") -> -12.5 | I46: =IF(H46="","",10^H46*Ksat_Lookup!$B$5) -> 3.1021944e-06 | J46: =IF(I46="","",I46*Ksat_Lookup!$B$6) -> 0.26802959
A47: 46 | B47: mJi | C47: Plutonic | D47: Middle Jurassic | E47: Middle Jurassic | F47: Crystalline rocks | G47: Plutonic -> crystalline | H47: =IFERROR(INDEX(Ksat_Lookup!$B$9:$B$18,MATCH(F47,Ksat_Lookup!$A$9:$A$18,0)),"") -> -14.1 | I47: =IF(H47="","",10^H47*Ksat_Lookup!$B$5) -> 7.79236e-08 | J47: =IF(I47="","",I47*Ksat_Lookup!$B$6) -> 0.006732599
... A198: 197 | B198: Xqz | C198: Sedimentary | D198: Early Proterozoic | E198: Early Proterozoic | F198: Siliciclastic sedimentary rocks | G198: Pre-Quaternary sedimentary rock (lithology not given) -> siliciclastic, undifferentiated | H198: =IFERROR(INDEX(Ksat_Lookup!$B$9:$B$18,MATCH(F198,Ksat_Lookup!$A$9:$A$18,0)),"") -> -15.2 | I198: =IF(H198="","",10^H198*Ksat_Lookup!$B$5) -> 6.1896915e-09 | J198: =IF(I198="","",I198*Ksat_Lookup!$B$6) -> 0.00053478935
A199: 198 | B199: Wvm | C199: Volcanic | D199: Late Archean | E199: Late Archean | F199: Volcanic rocks | G199: Precambrian volcanic; often metamorphosed (greenstone) - crystalline value may fit better | H199: =IFERROR(INDEX(Ksat_Lookup!$B$9:$B$18,MATCH(F199,Ksat_Lookup!$A$9:$A$18,0)),"") -> -12.5 | I199: =IF(H199="","",10^H199*Ksat_Lookup!$B$5) -> 3.1021944e-06 | J199: =IF(I199="","",I199*Ksat_Lookup!$B$6) -> 0.26802959 | K199: Crystalline rocks | L199: =10^INDEX(Ksat_Lookup!$B$9:$B$18,MATCH(K199,Ksat_Lookup!$A$9:$A$18,0))*Ksat_Lookup!$B$5*Ksat_Lookup!$B$6 -> 0.006732599
A200: 199 | B200: W | C200: Sedimentary | D200: Late Archean | E200: Late Archean | F200: Siliciclastic sedimentary rocks | G200: Pre-Quaternary sedimentary rock (lithology not given) -> siliciclastic, undifferentiated | H200: =IFERROR(INDEX(Ksat_Lookup!$B$9:$B$18,MATCH(F200,Ksat_Lookup!$A$9:$A$18,0)),"") -> -15.2 | I200: =IF(H200="","",10^H200*Ksat_Lookup!$B$5) -> 6.1896915e-09 | J200: =IF(I200="","",I200*Ksat_Lookup!$B$6) -> 0.00053478935
A201: 200 | B201: Zg | C201: Plutonic | D201: Late Proterozoic | E201: Late Proterozoic | F201: Crystalline rocks | G201: Plutonic -> crystalline | H201: =IFERROR(INDEX(Ksat_Lookup!$B$9:$B$18,MATCH(F201,Ksat_Lookup!$A$9:$A$18,0)),"") -> -14.1 | I201: =IF(H201="","",10^H201*Ksat_Lookup!$B$5) -> 7.79236e-08 | J201: =IF(I201="","",I201*Ksat_Lookup!$B$6) -> 0.006732599
A202: 201 | B202: 2uPA | C202: Sedimentary | D202: Upper Pennsylvanian | E202: Upper Pennsylvanian | F202: Siliciclastic sedimentary rocks | G202: Pre-Quaternary sedimentary rock (lithology not given) -> siliciclastic, undifferentiated | H202: =IFERROR(INDEX(Ksat_Lookup!$B$9:$B$18,MATCH(F202,Ksat_Lookup!$A$9:$A$18,0)),"") -> -15.2 | I202: =IF(H202="","",10^H202*Ksat_Lookup!$B$5) -> 6.1896915e-09 | J202: =IF(I202="","",I202*Ksat_Lookup!$B$6) -> 0.00053478935
A203: 202 | B203: Wt | C203: Plutonic | D203: Late Archean | E203: Late Archean | F203: Crystalline rocks | G203: Plutonic -> crystalline | H203: =IFERROR(INDEX(Ksat_Lookup!$B$9:$B$18,MATCH(F203,Ksat_Lookup!$A$9:$A$18,0)),"") -> -14.1 | I203: =IF(H203="","",10^H203*Ksat_Lookup!$B$5) -> 7.79236e-08 | J203: =IF(I203="","",I203*Ksat_Lookup!$B$6) -> 0.006732599
A204: 203 | B204: Wtn | C204: Metamorphic and undivided crystalline | D204: Late Archean | E204: Late Archean | F204: Crystalline rocks | G204: Metamorphic / undivided crystalline -> crystalline | H204: =IFERROR(INDEX(Ksat_Lookup!$B$9:$B$18,MATCH(F204,Ksat_Lookup!$A$9:$A$18,0)),"") -> -14.1 | I204: =IF(H204="","",10^H204*Ksat_Lookup!$B$5) -> 7.79236e-08 | J204: =IF(I204="","",I204*Ksat_Lookup!$B$6) -> 0.006732599
A205: 204 | B205: SM | C205: Plutonic | D205: Silurian | E205: Silurian | F205: Crystalline rocks | G205: Plutonic -> crystalline | H205: =IFERROR(INDEX(Ksat_Lookup!$B$9:$B$18,MATCH(F205,Ksat_Lookup!$A$9:$A$18,0)),"") -> -14.1 | I205: =IF(H205="","",10^H205*Ksat_Lookup!$B$5) -> 7.79236e-08 | J205: =IF(I205="","",I205*Ksat_Lookup!$B$6) -> 0.006732599
A206: 205 | B206: Wgt | C206: Plutonic | D206: Late Archean | E206: Late Archean | F206: Crystalline rocks | G206: Plutonic -> crystalline | H206: =IFERROR(INDEX(Ksat_Lookup!$B$9:$B$18,MATCH(F206,Ksat_Lookup!$A$9:$A$18,0)),"") -> -14.1 | I206: =IF(H206="","",10^H206*Ksat_Lookup!$B$5) -> 7.79236e-08 | J206: =IF(I206="","",I206*Ksat_Lookup!$B$6) -> 0.006732599
A207: 206 | B207: Wgg | C207: Plutonic | D207: Late Archean | E207: Late Archean | F207: Crystalline rocks | G207: Plutonic -> crystalline | H207: =IFERROR(INDEX(Ksat_Lookup!$B$9:$B$18,MATCH(F207,Ksat_Lookup!$A$9:$A$18,0)),"") -> -14.1 | I207: =IF(H207="","",10^H207*Ksat_Lookup!$B$5) -> 7.79236e-08 | J207: =IF(I207="","",I207*Ksat_Lookup!$B$6) -> 0.006732599
A208: 207 | B208: Ut | C208: Plutonic | D208: Early Archean | E208: Early Archean | F208: Crystalline rocks | G208: Plutonic -> crystalline | H208: =IFERROR(INDEX(Ksat_Lookup!$B$9:$B$18,MATCH(F208,Ksat_Lookup!$A$9:$A$18,0)),"") -> -14.1 | I208: =IF(H208="","",10^H208*Ksat_Lookup!$B$5) -> 7.79236e-08 | J208: =IF(I208="","",I208*Ksat_Lookup!$B$6) -> 0.006732599
A209: 208 | B209: X² | C209: Sedimentary | D209: Early Proterozoic | E209: Early Proterozoic | F209: Siliciclastic sedimentary rocks | G209: Pre-Quaternary sedimentary rock (lithology not given) -> siliciclastic, undifferentiated | H209: =IFERROR(INDEX(Ksat_Lookup!$B$9:$B$18,MATCH(F209,Ksat_Lookup!$A$9:$A$18,0)),"") -> -15.2 | I209: =IF(H209="","",10^H209*Ksat_Lookup!$B$5) -> 6.1896915e-09 | J209: =IF(I209="","",I209*Ksat_Lookup!$B$6) -> 0.00053478935
A210: 209 | B210: lM | C210: Sedimentary | D210: Lower Mississippian | E210: Lower Mississippian | F210: Siliciclastic sedimentary rocks | G210: Pre-Quaternary sedimentary rock (lithology not given) -> siliciclastic, undifferentiated | H210: =IFERROR(INDEX(Ksat_Lookup!$B$9:$B$18,MATCH(F210,Ksat_Lookup!$A$9:$A$18,0)),"") -> -15.2 | I210: =IF(H210="","",10^H210*Ksat_Lookup!$B$5) -> 6.1896915e-09 | J210: =IF(I210="","",I210*Ksat_Lookup!$B$6) -> 0.00053478935
...

Sheet Ksat_Lookup
A1: Conversion constants (permeability k -> hydraulic conductivity K = k*rho*g/mu)
A2: Water density rho (kg/m3) | B2: 1000
A3: Gravity g (m/s2) | B3: 9.81
A4: Dynamic viscosity mu (Pa s, ~20 C) | B4: 0.001
A5: Factor rho*g/mu (1/(m s)) | B5: =B2*B3/B4 -> 9810000
A6: Seconds per day | B6: 86400
A8: Hydrolithology | B8: log10 k mean (m2) | C8: log10 k SD | D8: Ksat (m/s) | E8: Ksat (m/day) | F8: Source / note
A9: Unconsolidated sediments | B9: -13 | C9: 2 | D9: =10^B9*$B$5 -> 9.81e-07 | E9: =D9*$B$6 -> 0.0847584 | F9: Gleeson et al. (2011) GRL 38:L02401, hydrolithology geometric means (also used in GLHYMPS 1.0)
A10: Siliciclastic sedimentary rocks | B10: -15.2 | C10: 2.5 | D10: =10^B10*$B$5 -> 6.1896915e-09 | E10: =D10*$B$6 -> 0.00053478935 | F10: Gleeson et al. (2011) GRL 38:L02401, hydrolithology geometric means (also used in GLHYMPS 1.0)
A11: Volcanic rocks | B11: -12.5 | C11: 1.8 | D11: =10^B11*$B$5 -> 3.1021944e-06 | E11: =D11*$B$6 -> 0.26802959 | F11: Gleeson et al. (2011) GRL 38:L02401, hydrolithology geometric means (also used in GLHYMPS 1.0)
A12: Crystalline rocks | B12: -14.1 | C12: 1.5 | D12: =10^B12*$B$5 -> 7.79236e-08 | E12: =D12*$B$6 -> 0.006732599 | F12: Gleeson et al. (2011) GRL 38:L02401, hydrolithology geometric means (also used in GLHYMPS 1.0)
A13: Mixed sedimentary-volcanic | B13: =AVERAGE(B10,B11) -> -13.85 | C13: =SQRT((C10^2+C11^2)/2) -> 2.1783021 | D13: =10^B13*$B$5 -> 1.3856993e-07 | E13: =D13*$B$6 -> 0.011972442 | F13: Derived: mean of siliciclastic and volcanic log k
A14: Carbonate rocks (ref.) | B14: -11.8 | C14: 1.5 | D14: =10^B14*$B$5 -> 1.5547802e-05 | E14: =D14*$B$6 -> 1.3433301 | F14: Gleeson et al. (2011) GRL 38:L02401, hydrolithology geometric means (also used in GLHYMPS 1.0) - not assigned (no carbonate info in codes)
A15: Unconsolidated coarse (ref.) | B15: -10.9 | C15: 1.2 | D15: =10^B15*$B$5 -> 0.00012350058 | E15: =D15*$B$6 -> 10.67045 | F15: Gleeson et al. (2011) GRL 38:L02401, hydrolithology geometric means (also used in GLHYMPS 1.0) - reference only
A16: Unconsolidated fine (ref.) | B16: -14 | C16: 1.8 | D16: =10^B16*$B$5 -> 9.81e-08 | E16: =D16*$B$6 -> 0.00847584 | F16: Gleeson et al. (2011) GRL 38:L02401, hydrolithology geometric means (also used in GLHYMPS 1.0) - reference only
A17: Siliciclastic coarse (ref.) | B17: -12.5 | C17: 0.9 | D17: =10^B17*$B$5 -> 3.1021944e-06 | E17: =D17*$B$6 -> 0.26802959 | F17: Gleeson et al. (2011) GRL 38:L02401, hydrolithology geometric means (also used in GLHYMPS 1.0) - reference only
A18: Siliciclastic fine (ref.) | B18: -16.5 | C18: 1.7 | D18: =10^B18*$B$5 -> 3.1021944e-10 | E18: =D18*$B$6 -> 2.6802959e-05 | F18: Gleeson et al. (2011) GRL 38:L02401, hydrolithology geometric means (also used in GLHYMPS 1.0) - reference only
A20: Notes
A21: Values are regional-scale (>5 km), ~upper 100 m, saturated. SD is ~1-2.5 orders of magnitude: treat as representative, not measured.
A22: Blue = hardcoded input (edit to change all classes). Black = formula.
A23: Values entered from Gleeson et al. (2011) Table 1 as recalled; verify against doi:10.1029/2010GL045565 before publication.
